Workbook

Sheet Réponses au formulaire 1
A1: Horodateur | B1: Nom | C1: Niveau_Études | D1: Réseau_Principal | E1: Usages | F1: Heures_Par_Jour | G1: Moyenne_Académique | H1: Nuisance_Concentration | I1: Heures_Sommeil
A2: 46095.517 | B2: Taleb | C2: Liscence 1 | D2: Youtube | E2: Recherche academique | F2: plus de 4h | G2: Plus de 16/20 | H2: 3 | I2: 5h a 6h
A3: 46095.521 | B3: Rokia Bettar | C3: Liscence 3 | D3: Tiktok | E3: Divertissement / detente, Communication avec amis, Actualités / informations | F3: plus de 4h | G3: Entre 12 et 14/20 | H3: 3 | I3: Moins de 5h
A4: 46095.524 | B4: Roukaye | C4: Liscence 1 | D4: Snapchat | E4: Communication avec amis, Autre | F4: Entre 3h et 4h | G4: Entre 10 et 12/20 | H4: 3 | I4: Moins de 5h
A5: 46095.538 | B5: N | C5: Liscence 1 | D5: Tiktok | E5: Divertissement / detente, Communication avec amis, Cours / tutoriels | F5: Entre 2h et 3h | G5: Entre 12 et 14/20 | H5: 5 | I5: Moins de 5h
A6: 46095.539 | B6: MOHAMED AHMED WALED | C6: Liscence 1 | D6: Tiktok | E6: Divertissement / detente, Communication avec amis | F6: plus de 4h | G6: Entre 12 et 14/20 | H6: 5 | I6: Moins de 5h
A7: 46095.543 | B7: Mamadou Sy | C7: Liscence 2 | D7: Tiktok | E7: Veille professionnelle | F7: Entre 1h et 2h | G7: Entre 10 et 12/20 | H7: 3 | I7: Moins de 5h
A8: 46095.56 | B8: محمد عبدو أكباد | C8: Liscence 1 | D8: Youtube | E8: Divertissement / detente, Communication avec amis, Recherche academique, Cours / tutoriels, Actualités / informations | F8: plus de 4h | G8: Entre 12 et 14/20 | H8: 3 | I8: 5h a 6h
A9: 46095.562 | B9: 25130 | C9: Liscence 1 | D9: Tiktok | E9: Autre | F9: plus de 4h | G9: Entre 12 et 14/20 | H9: 3 | I9: 5h a 6h
A10: 46095.563 | B10: Lashar medlemin | C10: Liscence 2 | D10: Youtube | E10: Cours / tutoriels | F10: Entre 2h et 3h | G10: Entre 12 et 14/20 | H10: 3 | I10: Moins de 5h
A11: 46095.563 | B11: Mohamed | C11: Master 1 | D11: Instagram | E11: Recherche academique | F11: plus de 4h | G11: Entre 10 et 12/20 | H11: 3 | I11: 7h a 8h
A12: 46095.564 | B12: Lashar | C12: Liscence 1 | D12: Snapchat | E12: Cours / tutoriels | F12: Entre 2h et 3h | G12: Entre 12 et 14/20 | H12: 4 | I12: 6h a 7h
A13: 46095.57 | B13: Moustapha | C13: Liscence 3 | D13: Facebook | E13: Cours / tutoriels | F13: Entre 3h et 4h | G13: Plus de 16/20 | H13: 5 | I13: Plus de 8h
A14: 46095.571 | B14: Khaled | C14: Master 2 | D14: Linkedln | E14: Recherche academique | F14: Entre 2h et 3h | G14: Plus de 16/20 | H14: 4 | I14: Plus de 8h
A15: 46095.572 | B15: Toto | C15: Liscence 3 | D15: Snapchat | E15: Communication avec amis | F15: Entre 2h et 3h | G15: Entre 12 et 14/20 | H15: 3 | I15: 7h a 8h
A16: 46095.639 | B16: Mohamed sidi Mohamed | C16: Liscence 1 | D16: Autres(preciser) | E16: Communication avec amis, Recherche academique, Cours / tutoriels | F16: Entre 2h et 3h | G16: Entre 10 et 12/20 | H16: 3 | I16: 6h a 7h

Sheet Analyse
A1: Analyse des données — Impact des réseaux sociaux sur les études
A2: Source : Google Forms • 15 réponses collectées • Mars 2026
A4: ■ ANALYSE DES DONNÉES DANS EXCEL
A6: Analyse numérique — Échelle de nuisance des réseaux sociaux sur la concentration (1 à 5)
A7: Indicateur | B7: Résultat
A8: Nombre de réponses | B8: =COUNT('Réponses au formulaire 1'!H2:H16) -> 15
A9: Valeur minimum | B9: =MIN('Réponses au formulaire 1'!H2:H16) -> 3
A10: Valeur maximum | B10: =MAX('Réponses au formulaire 1'!H2:H16) -> 5
A11: Moyenne | B11: =AVERAGE('Réponses au formulaire 1'!H2:H16) -> 3.5333333
A13: Analyse catégorielle — Réseau social le plus utilisé au quotidien
A14: Réseau Social | B14: Nombre de réponses | C14: Pourcentage
A15: Tiktok | B15: =COUNTIF('Réponses au formulaire 1'!D2:D16,"Tiktok") -> 5 | C15: =B15/15 -> 0.33333333
A16: Youtube | B16: =COUNTIF('Réponses au formulaire 1'!D2:D16,"Youtube") -> 3 | C16: =B16/15 -> 0.2
A17: Snapchat | B17: =COUNTIF('Réponses au formulaire 1'!D2:D16,"Snapchat") -> 3 | C17: =B17/15 -> 0.2
A18: Instagram | B18: =COUNTIF('Réponses au formulaire 1'!D2:D16,"Instagram") -> 1 | C18: =B18/15 -> 0.066666667
A19: Facebook | B19: =COUNTIF('Réponses au formulaire 1'!D2:D16,"Facebook") -> 1 | C19: =B19/15 -> 0.066666667
A20: Linkedln | B20: =COUNTIF('Réponses au formulaire 1'!D2:D16,"Linkedln") -> 1 | C20: =B20/15 -> 0.066666667
A21: Autres(preciser) | B21: =COUNTIF('Réponses au formulaire 1'!D2:D16,"Autres(preciser)") -> 1 | C21: =B21/15 -> 0.066666667
A22: TOTAL | B22: =SUM(B15:B21) -> 15 | C22: =B22/15 -> 1
A24: Analyse complémentaire — Temps passé sur les réseaux sociaux par jour
A25: Tranche horaire | B25: Nombre de réponses | C25: Pourcentage
A26: Moins de 1h | B26: =COUNTIF('Réponses au formulaire 1'!F2:F16,"Moins de 1h") -> 0 | C26: =B26/15 -> 0
A27: Entre 1h et 2h | B27: =COUNTIF('Réponses au formulaire 1'!F2:F16,"Entre 1h et 2h") -> 1 | C27: =B27/15 -> 0.066666667
A28: Entre 2h et 3h | B28: =COUNTIF('Réponses au formulaire 1'!F2:F16,"Entre 2h et 3h") -> 6 | C28: =B28/15 -> 0.4
A29: Entre 3h et 4h | B29: =COUNTIF('Réponses au formulaire 1'!F2:F16,"Entre 3h et 4h") -> 2 | C29: =B29/15 -> 0.13333333
A30: plus de 4h | B30: =COUNTIF('Réponses au formulaire 1'!F2:F16,"plus de 4h") -> 6 | C30: =B30/15 -> 0.4
A31: TOTAL | B31: =SUM(B26:B30) -> 15 | C31: =B31/15 -> 1
A33: ■ GRAPHIQUES
E35: Tiktok | F35: =COUNTIF('Réponses au formulaire 1'!D2:D16,"Tiktok") -> 5
E36: Youtube | F36: =COUNTIF('Réponses au formulaire 1'!D2:D16,"Youtube") -> 3
E37: Snapchat | F37: =COUNTIF('Réponses au formulaire 1'!D2:D16,"Snapchat") -> 3
E38: Instagram | F38: =COUNTIF('Réponses au formulaire 1'!D2:D16,"Instagram") -> 1
E39: Facebook | F39: =COUNTIF('Réponses au formulaire 1'!D2:D16,"Facebook") -> 1
E40: Linkedln | F40: =COUNTIF('Réponses au formulaire 1'!D2:D16,"Linkedln") -> 1
E41: Autres(preciser) | F41: =COUNTIF('Réponses au formulaire 1'!D2:D16,"Autres(preciser)") -> 1
E43: Moins de 1h | F43: =COUNTIF('Réponses au formulaire 1'!F2:F16,"Moins de 1h") -> 0
E44: Entre 1h et 2h | F44: =COUNTIF('Réponses au formulaire 1'!F2:F16,"Entre 1h et 2h") -> 1
E45: Entre 2h et 3h | F45: =COUNTIF('Réponses au formulaire 1'!F2:F16,"Entre 2h et 3h") -> 6
E46: Entre 3h et 4h | F46: =COUNTIF('Réponses au formulaire 1'!F2:F16,"Entre 3h et 4h") -> 2
E47: plus de 4h | F47: =COUNTIF('Réponses au formulaire 1'!F2:F16,"plus de 4h") -> 6
...
